Workbook

Sheet data_export
A1: program_label_short | B1: transfer | C1: wtp_env | D1: env_cost_wtp | E1: cost_wtp | F1: producers | G1: WTP | H1: fisc_tot | I1: cost | J1: MVPF
A2: Wind Production Credits | B2: 1 | C2: 4.24778 | D2: 1.900318 | E2: 0.6449316 | F2: 0 | G2: 7.79303 | H2: 0.3276403 | I2: 1.32764 | J2: 5.869835
A3: PTC (Shrimali) | B3: 1 | C3: 5.325597 | D3: 3.276529 | E3: 0.919621 | F3: 0 | G3: 10.52175 | H3: 0.3942201 | I3: 1.39422 | J3: 7.54669
A4: PTC (Metcalf) | B4: 1 | C4: 3.966325 | D4: 1.426829 | E4: 0.5598809 | F4: 0 | G4: 6.953035 | H4: 0.3123734 | I4: 1.312373 | J4: 5.298061
A5: PTC (Hitaj) | B5: 1 | C5: 3.451419 | D5: 0.9975948 | E5: 0.4552929 | F5: 0 | G5: 5.904307 | H5: 0.2763275 | I5: 1.276327 | J5: 4.626013
A6: Residential Solar | B6: 1.1056 | C6: 1.548539 | D6: 2.279867 | E6: 1.635643 | F6: -0.2137665 | G6: 6.355883 | H6: 0.6458964 | I6: 1.645896 | J6: 3.861654
A7: CSI | B7: 1 | C7: 3.875875 | D7: 4.987633 | E7: 3.98739 | F7: -0.5350411 | G7: 13.31586 | H7: 1.629892 | I7: 2.629892 | J7: 5.063271
A8: NE Solar | B8: 1 | C8: 1.099671 | D8: 3.132328 | E8: 1.609878 | F8: -0.1518029 | G8: 6.690074 | H8: 0.4307094 | I8: 1.430709 | J8: 4.676054
A9: CSI (TPO) | B9: 1.528 | C9: 1.446457 | D9: 1.982251 | E9: 1.371067 | F9: -0.1996747 | G9: 6.128101 | H9: 0.6061215 | I9: 1.606121 | J9: 3.815466
A10: CSI (HO) | B10: 1 | C10: 0.8401305 | D10: 1.081114 | E10: 0.8643025 | F10: -0.1159749 | G10: 3.669572 | H10: 0.3532937 | I10: 1.353294 | J10: 2.711586
A11: CT Solar | B11: 1 | C11: 0.4805634 | D11: 0.2160097 | E11: 0.3455759 | F11: -0.0663389 | G11: 1.97581 | H11: 0.2094654 | I11: 1.209465 | J11: 1.633623
A12: Electric Vehicles | B12: 1 | C12: 0.0889978 | D12: 0.0733491 | E12: 0.4516476 | F12: -0.0427899 | G12: 1.571205 | H12: 0.0871514 | I12: 1.087151 | J12: 1.445249
A13: BEV (State - Rebate) | B13: 1 | C13: 0.1067966 | D13: 0.1027134 | E13: 0.5637379 | F13: -0.0513475 | G13: 1.7219 | H13: 0.1028943 | I13: 1.102894 | J13: 1.561256
... A92: WAP (Mexico) | B92: 0.5 | C92: -0.0775422 | D92: 0 | E92: 0 | F92: 0 | G92: 0.4224578 | H92: 0.0015143 | I92: 1.001514 | J92: 0.421819

Sheet TABLE
J8: Willingness to Pay | R8: Cost
M10: Learning by Doing
F11: Panel A. Subsidies | J11: Transfer | K11: Env. Benefits | M11: Env. | N11: Price | O11: Profits | P11: WTP | R11: Fiscal Externality | S11: Total | T11: MVPF
G13: =data_export!A2 -> Wind Production Credits | J13: =IF(data_export!B2=0, "", data_export!B2) -> 1 | K13: =IF(data_export!C2=0, "", data_export!C2) -> 4.24778 | M13: =IF(data_export!D2=0, "", data_export!D2) -> 1.900318 | N13: =IF(data_export!E2=0, "", data_export!E2) -> 0.6449316 | O13: =IF(data_export!F2=0, "", data_export!F2) | P13: =IF(data_export!G2=0, "", data_export!G2) -> 7.79303 | R13: =IF(data_export!H2=0, "", data_export!H2) -> 0.3276403 | S13: =IF(data_export!I2=0, "", data_export!I2) -> 1.32764 | T13: =IF(data_export!J2=0, "", data_export!J2) -> 5.869835
H14: =data_export!A3 -> PTC (Shrimali) | J14: =IF(data_export!B3=0, "", data_export!B3) -> 1 | K14: =IF(data_export!C3=0, "", data_export!C3) -> 5.325597 | M14: =IF(data_export!D3=0, "", data_export!D3) -> 3.276529 | N14: =IF(data_export!E3=0, "", data_export!E3) -> 0.919621 | O14: =IF(data_export!F3=0, "", data_export!F3) | P14: =IF(data_export!G3=0, "", data_export!G3) -> 10.52175 | R14: =IF(data_export!H3=0, "", data_export!H3) -> 0.3942201 | S14: =IF(data_export!I3=0, "", data_export!I3) -> 1.39422 | T14: =IF(data_export!J3=0, "", data_export!J3) -> 7.54669
H15: =data_export!A4 -> PTC (Metcalf) | J15: =IF(data_export!B4=0, "", data_export!B4) -> 1 | K15: =IF(data_export!C4=0, "", data_export!C4) -> 3.966325 | M15: =IF(data_export!D4=0, "", data_export!D4) -> 1.426829 | N15: =IF(data_export!E4=0, "", data_export!E4) -> 0.5598809 | O15: =IF(data_export!F4=0, "", data_export!F4) | P15: =IF(data_export!G4=0, "", data_export!G4) -> 6.953035 | R15: =IF(data_export!H4=0, "", data_export!H4) -> 0.3123734 | S15: =IF(data_export!I4=0, "", data_export!I4) -> 1.312373 | T15: =IF(data_export!J4=0, "", data_export!J4) -> 5.298061
H16: =data_export!A5 -> PTC (Hitaj) | J16: =IF(data_export!B5=0, "", data_export!B5) -> 1 | K16: =IF(data_export!C5=0, "", data_export!C5) -> 3.451419 | M16: =IF(data_export!D5=0, "", data_export!D5) -> 0.9975948 | N16: =IF(data_export!E5=0, "", data_export!E5) -> 0.4552929 | O16: =IF(data_export!F5=0, "", data_export!F5) | P16: =IF(data_export!G5=0, "", data_export!G5) -> 5.904307 | R16: =IF(data_export!H5=0, "", data_export!H5) -> 0.2763275 | S16: =IF(data_export!I5=0, "", data_export!I5) -> 1.276327 | T16: =IF(data_export!J5=0, "", data_export!J5) -> 4.626013
H18: =data_export!A6 -> Residential Solar | J18: =IF(data_export!B6=0, "", data_export!B6) -> 1.1056 | K18: =IF(data_export!C6=0, "", data_export!C6) -> 1.548539 | M18: =IF(data_export!D6=0, "", data_export!D6) -> 2.279867 | N18: =IF(data_export!E6=0, "", data_export!E6) -> 1.635643 | O18: =IF(data_export!F6=0, "", data_export!F6) -> -0.2137665 | P18: =IF(data_export!G6=0, "", data_export!G6) -> 6.355883 | R18: =IF(data_export!H6=0, "", data_export!H6) -> 0.6458964 | S18: =IF(data_export!I6=0, "", data_export!I6) -> 1.645896 | T18: =IF(data_export!J6=0, "", data_export!J6) -> 3.861654
H19: =data_export!A7 -> CSI | J19: =IF(data_export!B7=0, "", data_export!B7) -> 1 | K19: =IF(data_export!C7=0, "", data_export!C7) -> 3.875875 | M19: =IF(data_export!D7=0, "", data_export!D7) -> 4.987633 | N19: =IF(data_export!E7=0, "", data_export!E7) -> 3.98739 | O19: =IF(data_export!F7=0, "", data_export!F7) -> -0.5350411 | P19: =IF(data_export!G7=0, "", data_export!G7) -> 13.31586 | R19: =IF(data_export!H7=0, "", data_export!H7) -> 1.629892 | S19: =IF(data_export!I7=0, "", data_export!I7) -> 2.629892 | T19: =IF(data_export!J7=0, "", data_export!J7) -> 5.063271
H20: =data_export!A8 -> NE Solar | J20: =IF(data_export!B8=0, "", data_export!B8) -> 1 | K20: =IF(data_export!C8=0, "", data_export!C8) -> 1.099671 | M20: =IF(data_export!D8=0, "", data_export!D8) -> 3.132328 | N20: =IF(data_export!E8=0, "", data_export!E8) -> 1.609878 | O20: =IF(data_export!F8=0, "", data_export!F8) -> -0.1518029 | P20: =IF(data_export!G8=0, "", data_export!G8) -> 6.690074 | R20: =IF(data_export!H8=0, "", data_export!H8) -> 0.4307094 | S20: =IF(data_export!I8=0, "", data_export!I8) -> 1.430709 | T20: =IF(data_export!J8=0, "", data_export!J8) -> 4.676054
H21: =data_export!A9 -> CSI (TPO) | J21: =IF(data_export!B9=0, "", data_export!B9) -> 1.528 | K21: =IF(data_export!C9=0, "", data_export!C9) -> 1.446457 | M21: =IF(data_export!D9=0, "", data_export!D9) -> 1.982251 | N21: =IF(data_export!E9=0, "", data_export!E9) -> 1.371067 | O21: =IF(data_export!F9=0, "", data_export!F9) -> -0.1996747 | P21: =IF(data_export!G9=0, "", data_export!G9) -> 6.128101 | R21: =IF(data_export!H9=0, "", data_export!H9) -> 0.6061215 | S21: =IF(data_export!I9=0, "", data_export!I9) -> 1.606121 | T21: =IF(data_export!J9=0, "", data_export!J9) -> 3.815466
H22: =data_export!A10 -> CSI (HO) | J22: =IF(data_export!B10=0, "", data_export!B10) -> 1 | K22: =IF(data_export!C10=0, "", data_export!C10) -> 0.8401305 | M22: =IF(data_export!D10=0, "", data_export!D10) -> 1.081114 | N22: =IF(data_export!E10=0, "", data_export!E10) -> 0.8643025 | O22: =IF(data_export!F10=0, "", data_export!F10) -> -0.1159749 | P22: =IF(data_export!G10=0, "", data_export!G10) -> 3.669572 | R22: =IF(data_export!H10=0, "", data_export!H10) -> 0.3532937 | S22: =IF(data_export!I10=0, "", data_export!I10) -> 1.353294 | T22: =IF(data_export!J10=0, "", data_export!J10) -> 2.711586
H23: =data_export!A11 -> CT Solar | J23: =IF(data_export!B11=0, "", data_export!B11) -> 1 | K23: =IF(data_export!C11=0, "", data_export!C11) -> 0.4805634 | M23: =IF(data_export!D11=0, "", data_export!D11) -> 0.2160097 | N23: =IF(data_export!E11=0, "", data_export!E11) -> 0.3455759 | O23: =IF(data_export!F11=0, "", data_export!F11) -> -0.0663389 | P23: =IF(data_export!G11=0, "", data_export!G11) -> 1.97581 | R23: =IF(data_export!H11=0, "", data_export!H11) -> 0.2094654 | S23: =IF(data_export!I11=0, "", data_export!I11) -> 1.209465 | T23: =IF(data_export!J11=0, "", data_export!J11) -> 1.633623
G25: =data_export!A12 -> Electric Vehicles | J25: =IF(data_export!B12=0, "", data_export!B12) -> 1 | K25: =IF(data_export!C12=0, "", data_export!C12) -> 0.0889978 | M25: =IF(data_export!D12=0, "", data_export!D12) -> 0.0733491 | N25: =IF(data_export!E12=0, "", data_export!E12) -> 0.4516476 | O25: =IF(data_export!F12=0, "", data_export!F12) -> -0.0427899 | P25: =IF(data_export!G12=0, "", data_export!G12) -> 1.571205 | R25: =IF(data_export!H12=0, "", data_export!H12) -> 0.0871514 | S25: =IF(data_export!I12=0, "", data_export!I12) -> 1.087151 | T25: =IF(data_export!J12=0, "", data_export!J12) -> 1.445249
H26: =data_export!A13 -> BEV (State - Rebate) | J26: =IF(data_export!B13=0, "", data_export!B13) -> 1 | K26: =IF(data_export!C13=0, "", data_export!C13) -> 0.1067966 | M26: =IF(data_export!D13=0, "", data_export!D13) -> 0.1027134 | N26: =IF(data_export!E13=0, "", data_export!E13) -> 0.5637379 | O26: =IF(data_export!F13=0, "", data_export!F13) -> -0.0513475 | P26: =IF(data_export!G13=0, "", data_export!G13) -> 1.7219 | R26: =IF(data_export!H13=0, "", data_export!H13) -> 0.1028943 | S26: =IF(data_export!I13=0, "", data_export!I13) -> 1.102894 | T26: =IF(data_export!J13=0, "", data_export!J13) -> 1.561256
H27: =data_export!A14 -> ITC (EV) | J27: =IF(data_export!B14=0, "", data_export!B14) -> 1 | K27: =IF(data_export!C14=0, "", data_export!C14) -> 0.0951507 | M27: =IF(data_export!D14=0, "", data_export!D14) -> 0.0777018 | N27: =IF(data_export!E14=0, "", data_export!E14) -> 0.4820471 | O27: =IF(data_export!F14=0, "", data_export!F14) -> -0.0457482 | P27: =IF(data_export!G14=0, "", data_export!G14) -> 1.609151 | R27: =IF(data_export!H14=0, "", data_export!H14) -> 0.0919185 | S27: =IF(data_export!I14=0, "", data_export!I14) -> 1.091918 | T27: =IF(data_export!J14=0, "", data_export!J14) -> 1.473692
H28: =data_export!A15 -> EFMP | J28: =IF(data_export!B15=0, "", data_export!B15) -> 1 | K28: =IF(data_export!C15=0, "", data_export!C15) -> 0.0650462 | M28: =IF(data_export!D15=0, "", data_export!D15) -> 0.0396321 | N28: =IF(data_export!E15=0, "", data_export!E15) -> 0.3091578 | O28: =IF(data_export!F15=0, "", data_export!F15) -> -0.0312741 | P28: =IF(data_export!G15=0, "", data_export!G15) -> 1.382562 | R28: =IF(data_export!H15=0, "", data_export!H15) -> 0.0666414 | S28: =IF(data_export!I15=0, "", data_export!I15) -> 1.066641 | T28: =IF(data_export!J15=0, "", data_export!J15) -> 1.296183
G30: =data_export!A16 -> Appliance Rebates | J30: =IF(data_export!B16=0, "", data_export!B16) -> 0.8674783 | K30: =IF(data_export!C16=0, "", data_export!C16) -> 0.4506499 | M30: =IF(data_export!D16=0, "", data_export!D16) | N30: =IF(data_export!E16=0, "", data_export!E16) | O30: =IF(data_export!F16=0, "", data_export!F16) -> -0.1031324 | P30: =IF(data_export!G16=0, "", data_export!G16) -> 1.214996 | R30: =IF(data_export!H16=0, "", data_export!H16) -> 0.0435868 | S30: =IF(data_export!I16=0, "", data_export!I16) -> 1.043587 | T30: =IF(data_export!J16=0, "", data_export!J16) -> 1.16425
H31: =data_export!A17 -> C4A (CW) | J31: =IF(data_export!B17=0, "", data_export!B17) -> 0.9525 | K31: =IF(data_export!C17=0, "", data_export!C17) -> 0.5088034 | M31: =IF(data_export!D17=0, "", data_export!D17) | N31: =IF(data_export!E17=0, "", data_export!E17) | O31: =IF(data_export!F17=0, "", data_export!F17) -> -0.0387521 | P31: =IF(data_export!G17=0, "", data_export!G17) -> 1.422551 | R31: =IF(data_export!H17=0, "", data_export!H17) -> 0.0124157 | S31: =IF(data_export!I17=0, "", data_export!I17) -> 1.012416 | T31: =IF(data_export!J17=0, "", data_export!J17) -> 1.405106
H32: =data_export!A18 -> ES (WH) | J32: =IF(data_export!B18=0, "", data_export!B18) -> 0.5978261 | K32: =IF(data_export!C18=0, "", data_export!C18) -> 1.505917 | M32: =IF(data_export!D18=0, "", data_export!D18) | N32: =IF(data_export!E18=0, "", data_export!E18) | O32: =IF(data_export!F18=0, "", data_export!F18) -> -0.6586787 | P32: =IF(data_export!G18=0, "", data_export!G18) -> 1.445065 | R32: =IF(data_export!H18=0, "", data_export!H18) -> 0.0783753 | S32: =IF(data_export!I18=0, "", data_export!I18) -> 1.078375 | T32: =IF(data_export!J18=0, "", data_export!J18) -> 1.340039
H33: =data_export!A19 -> ES (CW) | J33: =IF(data_export!B19=0, "", data_export!B19) -> 1 | K33: =IF(data_export!C19=0, "", data_export!C19) -> 0.7938316 | M33: =IF(data_export!D19=0, "", data_export!D19) | N33: =IF(data_export!E19=0, "", data_export!E19) | O33: =IF(data_export!F19=0, "", data_export!F19) -> -0.0718637 | P33: =IF(data_export!G19=0, "", data_export!G19) -> 1.721968 | R33: =IF(data_export!H19=0, "", data_export!H19) -> 0.314836 | S33: =IF(data_export!I19=0, "", data_export!I19) -> 1.314836 | T33: =IF(data_export!J19=0, "", data_export!J19) -> 1.309645
H34: =data_export!A20 -> C4A (DW) | J34: =IF(data_export!B20=0, "", data_export!B20) -> 0.9295 | K34: =IF(data_export!C20=0, "", data_export!C20) -> 0.2253946 | M34: =IF(data_export!D20=0, "", data_export!D20) | N34: =IF(data_export!E20=0, "", data_export!E20) | O34: =IF(data_export!F20=0, "", data_export!F20) -> -0.0166163 | P34: =IF(data_export!G20=0, "", data_export!G20) -> 1.138278 | R34: =IF(data_export!H20=0, "", data_export!H20) -> 0.0052036 | S34: =IF(data_export!I20=0, "", data_export!I20) -> 1.005204 | T34: =IF(data_export!J20=0, "", data_export!J20) -> 1.132386
H35: =data_export!A21 -> ES (DW) | J35: =IF(data_export!B21=0, "", data_export!B21) -> 1 | K35: =IF(data_export!C21=0, "", data_export!C21) -> -0.2053294 | M35: =IF(data_export!D21=0, "", data_export!D21) | N35: =IF(data_export!E21=0, "", data_export!E21) | O35: =IF(data_export!F21=0, "", data_export!F21) -> 0.018588 | P35: =IF(data_export!G21=0, "", data_export!G21) -> 0.8132586 | R35: =IF(data_export!H21=0, "", data_export!H21) -> -0.2279527 | S35: =IF(data_export!I21=0, "", data_export!I21) -> 0.7720473 | T35: =IF(data_export!J21=0, "", data_export!J21) -> 1.053379
H36: =data_export!A22 -> C4A (Fridge) | J36: =IF(data_export!B22=0, "", data_export!B22) -> 0.9599999 | K36: =IF(data_export!C22=0, "", data_export!C22) -> 0.0914723 | M36: =IF(data_export!D22=0, "", data_export!D22) | N36: =IF(data_export!E22=0, "", data_export!E22) | O36: =IF(data_export!F22=0, "", data_export!F22) -> -0.0071807 | P36: =IF(data_export!G22=0, "", data_export!G22) -> 1.044292 | R36: =IF(data_export!H22=0, "", data_export!H22) -> 0.0023472 | S36: =IF(data_export!I22=0, "", data_export!I22) -> 1.002347 | T36: =IF(data_export!J22=0, "", data_export!J22) -> 1.041846
H37: =data_export!A23 -> ES (Fridge) | J37: =IF(data_export!B23=0, "", data_export!B23) -> 1 | K37: =IF(data_export!C23=0, "", data_export!C23) -> 0.1832727 | M37: =IF(data_export!D23=0, "", data_export!D23) | N37: =IF(data_export!E23=0, "", data_export!E23) | O37: =IF(data_export!F23=0, "", data_export!F23) -> -0.0165912 | P37: =IF(data_export!G23=0, "", data_export!G23) -> 1.166681 | R37: =IF(data_export!H23=0, "", data_export!H23) -> 0.1535091 | S37: =IF(data_export!I23=0, "", data_export!I23) -> 1.153509 | T37: =IF(data_export!J23=0, "", data_export!J23) -> 1.011419
H38: =data_export!A24 -> CA ESA | J38: =IF(data_export!B24=0, "", data_export!B24) -> 0.5 | K38: =IF(data_export!C24=0, "", data_export!C24) -> 0.5018364 | M38: =IF(data_export!D24=0, "", data_export!D24) | N38: =IF(data_export!E24=0, "", data_export!E24) | O38: =IF(data_export!F24=0, "", data_export!F24) -> -0.0339649 | P38: =IF(data_export!G24=0, "", data_export!G24) -> 0.9678716 | R38: =IF(data_export!H24=0, "", data_export!H24) -> 0.00996 | S38: =IF(data_export!I24=0, "", data_export!I24) -> 1.00996 | T38: =IF(data_export!J24=0, "", data_export!J24) -> 0.9583266
G40: =data_export!A25 -> Vehicle Retirement | J40: =IF(data_export!B25=0, "", data_export!B25) -> 0.9101124 | K40: =IF(data_export!C25=0, "", data_export!C25) -> 0.24524 | M40: =IF(data_export!D25=0, "", data_export!D25) | N40: =IF(data_export!E25=0, "", data_export!E25) | O40: =IF(data_export!F25=0, "", data_export!F25) -> -0.0492736 | P40: =IF(data_export!G25=0, "", data_export!G25) -> 1.106079 | R40: =IF(data_export!H25=0, "", data_export!H25) -> 0.0559767 | S40: =IF(data_export!I25=0, "", data_export!I25) -> 1.055977 | T40: =IF(data_export!J25=0, "", data_export!J25) -> 1.047446
H41: =data_export!A26 -> C4C (TX) | J41: =IF(data_export!B26=0, "", data_export!B26) -> 1 | K41: =IF(data_export!C26=0, "", data_export!C26) -> 0.2313007 | M41: =IF(data_export!D26=0, "", data_export!D26) | N41: =IF(data_export!E26=0, "", data_export!E26) | O41: =IF(data_export!F26=0, "", data_export!F26) -> -0.0740984 | P41: =IF(data_export!G26=0, "", data_export!G26) -> 1.157202 | R41: =IF(data_export!H26=0, "", data_export!H26) -> 0.0844116 | S41: =IF(data_export!I26=0, "", data_export!I26) -> 1.084412 | T41: =IF(data_export!J26=0, "", data_export!J26) -> 1.067125
H42: =data_export!A27 -> C4C (US) | J42: =IF(data_export!B27=0, "", data_export!B27) -> 1 | K42: =IF(data_export!C27=0, "", data_export!C27) -> 0.1507279 | M42: =IF(data_export!D27=0, "", data_export!D27) | N42: =IF(data_export!E27=0, "", data_export!E27) | O42: =IF(data_export!F27=0, "", data_export!F27) -> -0.0486073 | P42: =IF(data_export!G27=0, "", data_export!G27) -> 1.102121 | R42: =IF(data_export!H27=0, "", data_export!H27) -> 0.0553809 | S42: =IF(data_export!I27=0, "", data_export!I27) -> 1.055381 | T42: =IF(data_export!J27=0, "", data_export!J27) -> 1.044287
H43: =data_export!A28 -> BAAQMD | J43: =IF(data_export!B28=0, "", data_export!B28) -> 0.7303371 | K43: =IF(data_export!C28=0, "", data_export!C28) -> 0.3536914 | M43: =IF(data_export!D28=0, "", data_export!D28) | N43: =IF(data_export!E28=0, "", data_export!E28) | O43: =IF(data_export!F28=0, "", data_export!F28) -> -0.0251152 | P43: =IF(data_export!G28=0, "", data_export!G28) -> 1.058913 | R43: =IF(data_export!H28=0, "", data_export!H28) -> 0.0281376 | S43: =IF(data_export!I28=0, "", data_export!I28) -> 1.028138 | T43: =IF(data_export!J28=0, "", data_export!J28) -> 1.029933
G45: =data_export!A29 -> Hybrid Vehicles | J45: =IF(data_export!B29=0, "", data_export!B29) -> 1 | K45: =IF(data_export!C29=0, "", data_export!C29) -> 0.0081383 | M45: =IF(data_export!D29=0, "", data_export!D29) -> 0.0003883 | N45: =IF(data_export!E29=0, "", data_export!E29) -> 0.0138026 | O45: =IF(data_export!F29=0, "", data_export!F29) -> -0.0064311 | P45: =IF(data_export!G29=0, "", data_export!G29) -> 1.015898 | R45: =IF(data_export!H29=0, "", data_export!H29) -> 0.003684 | S45: =IF(data_export!I29=0, "", data_export!I29) -> 1.003684 | T45: =IF(data_export!J29=0, "", data_export!J29) -> 1.012169
H46: =data_export!A30 -> HY (S-STW) | J46: =IF(data_export!B30=0, "", data_export!B30) -> 1 | K46: =IF(data_export!C30=0, "", data_export!C30) -> 0.0180959 | M46: =IF(data_export!D30=0, "", data_export!D30) -> 0.0010737 | N46: =IF(data_export!E30=0, "", data_export!E30) -> 0.0308237 | O46: =IF(data_export!F30=0, "", data_export!F30) -> -0.0142997 | P46: =IF(data_export!G30=0, "", data_export!G30) -> 1.035694 | R46: =IF(data_export!H30=0, "", data_export!H30) -> 0.0081832 | S46: =IF(data_export!I30=0, "", data_export!I30) -> 1.008183 | T46: =IF(data_export!J30=0, "", data_export!J30) -> 1.027287
H47: =data_export!A31 -> HY (F-ITC) | J47: =IF(data_export!B31=0, "", data_export!B31) -> 1 | K47: =IF(data_export!C31=0, "", data_export!C31) -> 0.0051932 | M47: =IF(data_export!D31=0, "", data_export!D31) -> 8.7e-05 | N47: =IF(data_export!E31=0, "", data_export!E31) -> 0.0087061 | O47: =IF(data_export!F31=0, "", data_export!F31) -> -0.0041038 | P47: =IF(data_export!G31=0, "", data_export!G31) -> 1.009883 | R47: =IF(data_export!H31=0, "", data_export!H31) -> 0.0023571 | S47: =IF(data_export!I31=0, "", data_export!I31) -> 1.002357 | T47: =IF(data_export!J31=0, "", data_export!J31) -> 1.007508
H48: =data_export!A32 -> HY (S-ITC) | J48: =IF(data_export!B32=0, "", data_export!B32) -> 1 | K48: =IF(data_export!C32=0, "", data_export!C32) -> 0.0011259 | M48: =IF(data_export!D32=0, "", data_export!D32) -> 4.07e-06 | N48: =IF(data_export!E32=0, "", data_export!E32) -> 0.0018782 | O48: =IF(data_export!F32=0, "", data_export!F32) -> -0.0008897 | P48: =IF(data_export!G32=0, "", data_export!G32) -> 1.002118 | R48: =IF(data_export!H32=0, "", data_export!H32) -> 0.0005116 | S48: =IF(data_export!I32=0, "", data_export!I32) -> 1.000512 | T48: =IF(data_export!J32=0, "", data_export!J32) -> 1.001606
G50: =data_export!A33 -> Weatherization | J50: =IF(data_export!B33=0, "", data_export!B33) -> 0.7740969 | K50: =IF(data_export!C33=0, "", data_export!C33) -> 0.2691714 | M50: =IF(data_export!D33=0, "", data_export!D33) | N50: =IF(data_export!E33=0, "", data_export!E33) | O50: =IF(data_export!F33=0, "", data_export!F33) -> -0.0541347 | P50: =IF(data_export!G33=0, "", data_export!G33) -> 0.9891335 | R50: =IF(data_export!H33=0, "", data_export!H33) -> 0.0117654 | S50: =IF(data_export!I33=0, "", data_export!I33) -> 1.011765 | T50: =IF(data_export!J33=0, "", data_export!J33) -> 0.9776313
H51: =data_export!A34 -> EPP | J51: =IF(data_export!B34=0, "", data_export!B34) -> 0.7500001 | K51: =IF(data_export!C34=0, "", data_export!C34) -> 0.5441011 | M51: =IF(data_export!D34=0, "", data_export!D34) | N51: =IF(data_export!E34=0, "", data_export!E34) | O51: =IF(data_export!F34=0, "", data_export!F34) -> -0.0574578 | P51: =IF(data_export!G34=0, "", data_export!G34) -> 1.236643 | R51: =IF(data_export!H34=0, "", data_export!H34) -> 0.0218937 | S51: =IF(data_export!I34=0, "", data_export!I34) -> 1.021894 | T51: =IF(data_export!J34=0, "", data_export!J34) -> 1.210149
H52: =data_export!A35 -> IHWAP | J52: =IF(data_export!B35=0, "", data_export!B35) -> 0.75 | K52: =IF(data_export!C35=0, "", data_export!C35) -> 0.3591664 | M52: =IF(data_export!D35=0, "", data_export!D35) | N52: =IF(data_export!E35=0, "", data_export!E35) | O52: =IF(data_export!F35=0, "", data_export!F35) -> -0.1105859 | P52: =IF(data_export!G35=0, "", data_export!G35) -> 0.9985805 | R52: =IF(data_export!H35=0, "", data_export!H35) -> 0.0187697 | S52: =IF(data_export!I35=0, "", data_export!I35) -> 1.01877 | T52: =IF(data_export!J35=0, "", data_export!J35) -> 0.9801827
H53: =data_export!A36 -> WI RF | J53: =IF(data_export!B36=0, "", data_export!B36) -> 0.8704846 | K53: =IF(data_export!C36=0, "", data_export!C36) -> 0.0501621 | M53: =IF(data_export!D36=0, "", data_export!D36) | N53: =IF(data_export!E36=0, "", data_export!E36) | O53: =IF(data_export!F36=0, "", data_export!F36) -> -0.0010531 | P53: =IF(data_export!G36=0, "", data_export!G36) -> 0.9195937 | R53: =IF(data_export!H36=0, "", data_export!H36) -> -0.0002387 | S53: =IF(data_export!I36=0, "", data_export!I36) -> 0.9997613 | T53: =IF(data_export!J36=0, "", data_export!J36) -> 0.9198132
H54: =data_export!A37 -> WAP | J54: =IF(data_export!B37=0, "", data_export!B37) -> 0.7500001 | K54: =IF(data_export!C37=0, "", data_export!C37) -> 0.2654865 | M54: =IF(data_export!D37=0, "", data_export!D37) | N54: =IF(data_export!E37=0, "", data_export!E37) | O54: =IF(data_export!F37=0, "", data_export!F37) -> -0.0881718 | P54: =IF(data_export!G37=0, "", data_export!G37) -> 0.9273148 | R54: =IF(data_export!H37=0, "", data_export!H37) -> 0.0132946 | S54: =IF(data_export!I37=0, "", data_export!I37) -> 1.013295 | T54: =IF(data_export!J37=0, "", data_export!J37) -> 0.9151483
H55: =data_export!A38 -> LEEP+ | J55: =IF(data_export!B38=0, "", data_export!B38) -> 0.7499999 | K55: =IF(data_export!C38=0, "", data_export!C38) -> 0.1269407 | M55: =IF(data_export!D38=0, "", data_export!D38) | N55: =IF(data_export!E38=0, "", data_export!E38) | O55: =IF(data_export!F38=0, "", data_export!F38) -> -0.0134051 | P55: =IF(data_export!G38=0, "", data_export!G38) -> 0.8635356 | R55: =IF(data_export!H38=0, "", data_export!H38) -> 0.0051079 | S55: =IF(data_export!I38=0, "", data_export!I38) -> 1.005108 | T55: =IF(data_export!J38=0, "", data_export!J38) -> 0.8591472
...
